# Исключения
В Python, если дело пахнет жареным, используется **исключение**: код, который выполняется, когда происходит связанная с ним ошибка.

Чтобы пользователь знал о происходящем, рекомендуется добавлять **обработчики исключений** везде, где исключение может быть сгенерировано. Не всегда у вас получится исправить ошибку, но вы хотя бы будете знать, при каких обстоятельствах она появилась, и аккуратно завершите программу. Если исключение сгенерировалось в функции и там не обработалось, оно будет всплывать до тех пор, пока его не поймает соответствующий обработчик в одной из вызывающих функций. Если вы не предоставите собственный обработчик исключений, Python выведет сообщение об ошибке и некоторую информацию о том, где произошла ошибка, а затем завершит программу, как показано в следующем фрагменте кода:

```python
short_list = [1, 2, 3]
position = 5
short_list[position]
# Traceback (most recent call last):
# File "<stdin>", line 1, in <module>
# IndexError: list index out of range
```

## try except
*Делай или не делай. Не надо пытаться*.
- Йода

Вместо того чтобы полагаться на волю случая, размещайте свой код в блоке try и используйте блок except для обработки ошибки:
```python
short_list = [1, 2, 3]
position = 5
try:
	short_list[position]
except:
	print('Need a position between 0 and', len(short_list)-1, ' but got', position)

# Need a position between 0 and 2 but got 5
```

- Запускается код внутри блока `try`.
- Если произошла ошибка:
	- Генерируется исключение
	- Выполняется код, расположенный внутри блока `except`. 
- Если ошибок не произошло, блок except пропускается

Иногда вам будут нужны и другие подробности исключения. Вы можете получить объект исключения целиком в переменной имя, если используете такую форму:

```
except тип_исключения as имя
```

```python
short_list = [1, 2, 3]
while True:
	value = input('Position [q to quit]? ')
	if value == 'q':
		break
	try:
		position = int(value)
		print(short_list[position])
	except IndexError as err:
		print('Bad index:', position)
	except Exception as other:
		print('Something else broke:', other)
```
